<?xml version="1.0" encoding="utf-8"?>
<!-- =================================================================================== -->
<!-- |    This document was autogenerated by xacro from BERT2.xacro                    | -->
<!-- |    EDITING THIS FILE BY HAND IS NOT RECOMMENDED                                 | -->
<!-- =================================================================================== -->
<robot name="BERT2_robot">
  <!-- Space btw top of beam and the each joint -->
  <!-- Make the robot's base immovable -->
  <link name="world"/>
  <joint name="fixed" type="fixed">
    <parent link="world"/>
    <child link="BERT2_baselink"/>
  </joint>
  <!-- Base Link -->
  <link name="BERT2_baselink">
    <collision>
      <origin rpy="0 0 0" xyz="0 0 0.25"/>
      <geometry>
        <box size="0.1 0.1 0.5"/>
      </geometry>
    </collision>
    <visual>
      <origin rpy="0 0 0" xyz="0 0 0.25"/>
      <geometry>
        <box size="0.1 0.1 0.5"/>
      </geometry>
      <material name="black"/>
    </visual>
    <inertial>
      <origin rpy="0 0 0" xyz="0 0 0.25"/>
      <mass value="5"/>
      <inertia ixx="0.108333333333" ixy="0.0" ixz="0.0" iyy="0.108333333333" iyz="0.0" izz="0.00833333333333"/>
    </inertial>
  </link>
  <joint name="BERT2_joint1" type="continuous">
    <parent link="BERT2_baselink"/>
    <child link="BERT2_link1"/>
    <origin rpy="0 0 0" xyz="0 0.1 0.475"/>
    <axis xyz="0 1 0"/>
    <dynamics damping="0.7"/>
  </joint>
  <!-- Middle Link -->
  <link name="BERT2_link1">
    <collision>
      <origin rpy="0 0 0" xyz="0 0 0.11175"/>
      <geometry>
        <cylinder length="0.2735" radius="0.05"/>
      </geometry>
    </collision>
    <visual>
      <origin rpy="0 0 0" xyz="0 0 0.11175"/>
      <geometry>
        <cylinder length="0.2735" radius="0.05"/>
      </geometry>
      <material name="grey"/>
    </visual>
    <inertial>
      <origin rpy="0 0 0" xyz="0 0 0.11175"/>
      <mass value="2.35"/>
      <inertia ixx="0.0161175239583" ixy="0.0" ixz="0.0" iyy="0.0161175239583" iyz="0.0" izz="0.0029375"/>
    </inertial>
  </link>
  <joint name="BERT2_joint2" type="continuous">
    <parent link="BERT2_link1"/>
    <child link="BERT2_link2"/>
    <origin rpy="0 0 0" xyz="0 0.1 0.2235"/>
    <axis xyz="0 1 0"/>
    <dynamics damping="0.7"/>
  </joint>
  <!-- Top Link -->
  <link name="BERT2_link2">
    <collision>
      <origin rpy="0 0 0" xyz="0 0 0.195"/>
      <geometry>
        <cylinder length="0.44" radius="0.05"/>
      </geometry>
    </collision>
    <visual>
      <origin rpy="0 0 0" xyz="0 0 0.195"/>
      <geometry>
        <cylinder length="0.44" radius="0.05"/>
      </geometry>
      <material name="black"/>
    </visual>
    <inertial>
      <origin rpy="0 0 0" xyz="0 0 0.195"/>
      <mass value="3.0"/>
      <inertia ixx="0.050275" ixy="0.0" ixz="0.0" iyy="0.050275" iyz="0.0" izz="0.00375"/>
    </inertial>
  </link>
  <!-- Transmissions -->
  <transmission name="BERT2_tran1">
    <type>transmission_interface/SimpleTransmission</type>
    <joint name="BERT2_joint1">
      <hardwareInterface>hardware_interface/EffortJointInterface</hardwareInterface>
    </joint>
    <actuator name="BERT2_motor1">
      <hardwareInterface>hardware_interface/EffortJointInterface</hardwareInterface>
      <mechanicalReduction>1</mechanicalReduction>
    </actuator>
  </transmission>
  <transmission name="BERT2_tran2">
    <type>transmission_interface/SimpleTransmission</type>
    <joint name="BERT2_joint2">
      <hardwareInterface>hardware_interface/EffortJointInterface</hardwareInterface>
    </joint>
    <actuator name="BERT2_motor2">
      <hardwareInterface>hardware_interface/EffortJointInterface</hardwareInterface>
      <mechanicalReduction>1</mechanicalReduction>
    </actuator>
  </transmission>
  <!-- Gazebo Plugins -->
  <gazebo>
    <plugin filename="libgazebo_ros_control.so" name="gazebo_ros_control">
      <robotNamespace>/BERT2_robot</robotNamespace>
      <robotSimType>gazebo_ros_control/DefaultRobotHWSim</robotSimType>
      <controlPeriod>0.01</controlPeriod>
    </plugin>
  </gazebo>
  <!-- Additional Configs -->
  <gazebo reference="BERT2_baselink">
    <material>Gazebo/Black</material>
  </gazebo>
  <gazebo reference="BERT2_link1">
    <mu1>0.2</mu1>
    <mu2>0.2</mu2>
    <material>Gazebo/Grey</material>
  </gazebo>
  <gazebo reference="BERT2_link2">
    <mu1>0.2</mu1>
    <mu2>0.2</mu2>
    <material>Gazebo/Black</material>
  </gazebo>
</robot>

